<?xml version="1.0" encoding="UTF-8"?>
<robot generator="Robot 7.0 (Python 3.12.3 on linux)" generated="2024-06-07T11:46:29.274163" rpa="false" schemaversion="5">
<suite id="s1" name="Test" source="/test">
<suite id="s1-s1" name="TestSuite" source="/test/TestSuite.robot">
<test id="s1-s1-t1" name="BearerAuthTest" line="12">
<kw name="Create Session" owner="RequestsLibrary">
<msg time="2024-06-07T11:46:29.374868" level="INFO">Creating Session using : alias=mysession, url=http://host.docker.internal:3000, headers={},                     cookies={}, auth=None, timeout=None, proxies=None, verify=False,                     debug=0 </msg>
<arg>mysession</arg>
<arg>${base_url}</arg>
<doc>Create Session: create a HTTP session to a server</doc>
<status status="PASS" start="2024-06-07T11:46:29.374708" elapsed="0.000472"/>
</kw>
<kw name="Create Dictionary" owner="BuiltIn">
<msg time="2024-06-07T11:46:29.375590" level="INFO">${headers} = {'Content-Type': 'application/json'}</msg>
<var>${headers}</var>
<arg>Content-Type=application/json</arg>
<doc>Creates and returns a dictionary based on the given ``items``.</doc>
<status status="PASS" start="2024-06-07T11:46:29.375295" elapsed="0.000316"/>
</kw>
<kw name="POST On Session" owner="RequestsLibrary">
<msg time="2024-06-07T11:46:29.379321" level="WARN">Retrying (RetryAdapter(total=2, connect=None, read=None, redirect=None, status=None)) after connection broken by 'NewConnectionError('&lt;urllib3.connection.HTTPConnection object at 0x7f1a009aa3f0&gt;: Failed to establish a new connection: [Errno 111] Connection refused')': /auth/login</msg>
<msg time="2024-06-07T11:46:29.581186" level="WARN">Retrying (RetryAdapter(total=1, connect=None, read=None, redirect=None, status=None)) after connection broken by 'NewConnectionError('&lt;urllib3.connection.HTTPConnection object at 0x7f1a0046c7d0&gt;: Failed to establish a new connection: [Errno 111] Connection refused')': /auth/login</msg>
<msg time="2024-06-07T11:46:29.983161" level="WARN">Retrying (RetryAdapter(total=0, connect=None, read=None, redirect=None, status=None)) after connection broken by 'NewConnectionError('&lt;urllib3.connection.HTTPConnection object at 0x7f1a0046ca40&gt;: Failed to establish a new connection: [Errno 111] Connection refused')': /auth/login</msg>
<msg time="2024-06-07T11:46:29.984505" level="FAIL">ConnectionError: HTTPConnectionPool(host='host.docker.internal', port=3000): Max retries exceeded with url: /auth/login (Caused by NewConnectionError('&lt;urllib3.connection.HTTPConnection object at 0x7f1a0046ccb0&gt;: Failed to establish a new connection: [Errno 111] Connection refused'))</msg>
<var>${resp}</var>
<arg>mysession</arg>
<arg>/auth/login</arg>
<arg>data={"email": "john.doe@domain.com", "password": "password"}</arg>
<arg>headers=${ headers }</arg>
<doc>Sends a POST request on a previously created HTTP Session.</doc>
<status status="FAIL" start="2024-06-07T11:46:29.375699" elapsed="0.613744">ConnectionError: HTTPConnectionPool(host='host.docker.internal', port=3000): Max retries exceeded with url: /auth/login (Caused by NewConnectionError('&lt;urllib3.connection.HTTPConnection object at 0x7f1a0046ccb0&gt;: Failed to establish a new connection: [Errno 111] Connection refused'))</status>
</kw>
<kw name="Get From Dictionary" owner="Collections">
<var>${token}</var>
<arg>${ resp.json() }</arg>
<arg>accessToken</arg>
<doc>Returns a value from the given ``dictionary`` based on the given ``key``.</doc>
<status status="NOT RUN" start="2024-06-07T11:46:29.989646" elapsed="0.000026"/>
</kw>
<kw name="Set Global Variable" owner="BuiltIn">
<arg>${accessToken}</arg>
<arg>Bearer ${token}</arg>
<doc>Makes a variable available globally in all tests and suites.</doc>
<status status="NOT RUN" start="2024-06-07T11:46:29.989795" elapsed="0.000022"/>
</kw>
<kw name="Delete All Sessions" owner="RequestsLibrary">
<doc>Removes all the session objects</doc>
<status status="NOT RUN" start="2024-06-07T11:46:29.989914" elapsed="0.000025"/>
</kw>
<status status="FAIL" start="2024-06-07T11:46:29.374111" elapsed="0.616001">ConnectionError: HTTPConnectionPool(host='host.docker.internal', port=3000): Max retries exceeded with url: /auth/login (Caused by NewConnectionError('&lt;urllib3.connection.HTTPConnection object at 0x7f1a0046ccb0&gt;: Failed to establish a new connection: [Errno 111] Connection refused'))</status>
</test>
<test id="s1-s1-t2" name="AppGetTest" line="23">
<kw name="Create Session" owner="RequestsLibrary">
<msg time="2024-06-07T11:46:29.990900" level="INFO">Creating Session using : alias=mysession, url=http://host.docker.internal:3000, headers={},                     cookies={}, auth=None, timeout=None, proxies=None, verify=False,                     debug=0 </msg>
<arg>mysession</arg>
<arg>${base_url}</arg>
<doc>Create Session: create a HTTP session to a server</doc>
<status status="PASS" start="2024-06-07T11:46:29.990731" elapsed="0.000341"/>
</kw>
<kw name="Create Dictionary" owner="BuiltIn">
<msg time="2024-06-07T11:46:29.991477" level="INFO">${headers} = {'Content-Type': 'application/json', 'Authorization': '"none"'}</msg>
<var>${headers}</var>
<arg>Content-Type=application/json</arg>
<arg>Authorization=${accessToken}</arg>
<doc>Creates and returns a dictionary based on the given ``items``.</doc>
<status status="PASS" start="2024-06-07T11:46:29.991204" elapsed="0.000300"/>
</kw>
<kw name="GET On Session" owner="RequestsLibrary">
<msg time="2024-06-07T11:46:29.992844" level="WARN">Retrying (RetryAdapter(total=2, connect=None, read=None, redirect=None, status=None)) after connection broken by 'NewConnectionError('&lt;urllib3.connection.HTTPConnection object at 0x7f1a0046f170&gt;: Failed to establish a new connection: [Errno 111] Connection refused')': /</msg>
<msg time="2024-06-07T11:46:30.195238" level="WARN">Retrying (RetryAdapter(total=1, connect=None, read=None, redirect=None, status=None)) after connection broken by 'NewConnectionError('&lt;urllib3.connection.HTTPConnection object at 0x7f1a0046f4a0&gt;: Failed to establish a new connection: [Errno 111] Connection refused')': /</msg>
<msg time="2024-06-07T11:46:30.597663" level="WARN">Retrying (RetryAdapter(total=0, connect=None, read=None, redirect=None, status=None)) after connection broken by 'NewConnectionError('&lt;urllib3.connection.HTTPConnection object at 0x7f1a0046f650&gt;: Failed to establish a new connection: [Errno 111] Connection refused')': /</msg>
<msg time="2024-06-07T11:46:30.599023" level="FAIL">ConnectionError: HTTPConnectionPool(host='host.docker.internal', port=3000): Max retries exceeded with url: / (Caused by NewConnectionError('&lt;urllib3.connection.HTTPConnection object at 0x7f1a0046f890&gt;: Failed to establish a new connection: [Errno 111] Connection refused'))</msg>
<var>${resp}</var>
<arg>mysession</arg>
<arg>/</arg>
<arg>headers=${ headers }</arg>
<doc>Sends a GET request on a previously created HTTP Session.</doc>
<status status="FAIL" start="2024-06-07T11:46:29.991621" elapsed="0.610878">ConnectionError: HTTPConnectionPool(host='host.docker.internal', port=3000): Max retries exceeded with url: / (Caused by NewConnectionError('&lt;urllib3.connection.HTTPConnection object at 0x7f1a0046f890&gt;: Failed to establish a new connection: [Errno 111] Connection refused'))</status>
</kw>
<kw name="Delete All Sessions" owner="RequestsLibrary">
<doc>Removes all the session objects</doc>
<status status="NOT RUN" start="2024-06-07T11:46:30.602718" elapsed="0.000031"/>
</kw>
<status status="FAIL" start="2024-06-07T11:46:29.990427" elapsed="0.612530">ConnectionError: HTTPConnectionPool(host='host.docker.internal', port=3000): Max retries exceeded with url: / (Caused by NewConnectionError('&lt;urllib3.connection.HTTPConnection object at 0x7f1a0046f890&gt;: Failed to establish a new connection: [Errno 111] Connection refused'))</status>
</test>
<status status="FAIL" start="2024-06-07T11:46:29.295489" elapsed="1.308047"/>
</suite>
<status status="FAIL" start="2024-06-07T11:46:29.274873" elapsed="1.329390"/>
</suite>
<statistics>
<total>
<stat pass="0" fail="2" skip="0">All Tests</stat>
</total>
<tag>
</tag>
<suite>
<stat pass="0" fail="2" skip="0" id="s1" name="Test">Test</stat>
<stat pass="0" fail="2" skip="0" id="s1-s1" name="TestSuite">Test.TestSuite</stat>
</suite>
</statistics>
<errors>
<msg time="2024-06-07T11:46:29.379321" level="WARN">Retrying (RetryAdapter(total=2, connect=None, read=None, redirect=None, status=None)) after connection broken by 'NewConnectionError('&lt;urllib3.connection.HTTPConnection object at 0x7f1a009aa3f0&gt;: Failed to establish a new connection: [Errno 111] Connection refused')': /auth/login</msg>
<msg time="2024-06-07T11:46:29.581186" level="WARN">Retrying (RetryAdapter(total=1, connect=None, read=None, redirect=None, status=None)) after connection broken by 'NewConnectionError('&lt;urllib3.connection.HTTPConnection object at 0x7f1a0046c7d0&gt;: Failed to establish a new connection: [Errno 111] Connection refused')': /auth/login</msg>
<msg time="2024-06-07T11:46:29.983161" level="WARN">Retrying (RetryAdapter(total=0, connect=None, read=None, redirect=None, status=None)) after connection broken by 'NewConnectionError('&lt;urllib3.connection.HTTPConnection object at 0x7f1a0046ca40&gt;: Failed to establish a new connection: [Errno 111] Connection refused')': /auth/login</msg>
<msg time="2024-06-07T11:46:29.992844" level="WARN">Retrying (RetryAdapter(total=2, connect=None, read=None, redirect=None, status=None)) after connection broken by 'NewConnectionError('&lt;urllib3.connection.HTTPConnection object at 0x7f1a0046f170&gt;: Failed to establish a new connection: [Errno 111] Connection refused')': /</msg>
<msg time="2024-06-07T11:46:30.195238" level="WARN">Retrying (RetryAdapter(total=1, connect=None, read=None, redirect=None, status=None)) after connection broken by 'NewConnectionError('&lt;urllib3.connection.HTTPConnection object at 0x7f1a0046f4a0&gt;: Failed to establish a new connection: [Errno 111] Connection refused')': /</msg>
<msg time="2024-06-07T11:46:30.597663" level="WARN">Retrying (RetryAdapter(total=0, connect=None, read=None, redirect=None, status=None)) after connection broken by 'NewConnectionError('&lt;urllib3.connection.HTTPConnection object at 0x7f1a0046f650&gt;: Failed to establish a new connection: [Errno 111] Connection refused')': /</msg>
</errors>
</robot>
